<?xml version="1.0"?>
<robot name="RPP_Robot">
  
  <material name="red">
    <color rgba="1 0 0 0.8" />
  </material>
  <material name="green">
    <color rgba="0 1 0 0.8" />
  </material>
<material name="blue">
    <color rgba="0 0 1 0.8" />
  </material>
<material name="yellow">
    <color rgba="1 1 0 0.8" />
  </material>

 
  <link name="base" />
  <link name="silindir">
    <visual>
      <geometry>
        <cylinder length="3" radius = "2"  />
      </geometry>
      <origin xyz="0 0 1.5" />
      <material name="red" />
    </visual>
  </link>
  <link name="silindir1">
    <visual>
      <geometry>
         <cylinder radius = "0.8" length="8" />
      </geometry>
      <origin xyz="0 0 -4 " />
      <material name="green" />
    </visual>
  </link>


<link name="prizma">
    <visual>
      <geometry>
       <box size="12 1 1" />
      </geometry>
      
      <material name="green" />
    </visual>
  </link>
<link name="kutu">
    <visual>
      <geometry>
       <box size="2 2 2" />
      </geometry>
      <material name="yellow" />
    </visual>
  </link>
<link name="end">
    <visual>
      <geometry>
       <box size=" 0.9 0.9 12" />
      </geometry>
      <origin xyz="0 0 6 " />
      <material name="blue" />
    </visual>
  </link>

  <joint name="j1" type="continuous">
    <parent link="base" />
    <child link="silindir" />
    <axis xyz="0 0 1" />
  </joint>
  
  <joint name="j2" type="fixed">
    <parent link="silindir" />
    <child link="silindir1" />
    <origin xyz="0 0 10" />
    
  </joint>
  

<joint name="j4" type="prismatic">
    <parent link="silindir1" />
    <child link="prizma" />
 <origin xyz="0 0 0.5" />
<limit effort="30" velocity="1.0" lower="-2.2" upper="5" />
<axis xyz="1 0 0" />

  </joint>
  <joint name="j5" type="fixed">
    <parent link="prizma" />
    <child link="kutu" />
    <origin xyz="6 0 0" />

  </joint>
<joint name="j6" type="prismatic">
    <parent link="kutu" />
    <child link="end" />
<origin xyz="0 0 -6" />
<limit effort="30" velocity="1.0" lower="-2.2" upper="5" />
<axis xyz="0 0 1" />
  </joint>

</robot>